2017-07-06 17:09:28,873 [Thread-3:4904] [django.request:152] [base:get_response] [WARNING]- Not Found: /static/blog/js/up/jquery.js
2017-07-06 17:09:28,874 [Thread-4:4764] [django.request:152] [base:get_response] [WARNING]- Not Found: /static/blog/js/up/js.js
2017-07-06 17:10:56,660 [Thread-3:4216] [django.request:152] [base:get_response] [WARNING]- Not Found: /static/blog/js/up/jquery.js
2017-07-06 17:10:56,665 [Thread-4:1940] [django.request:152] [base:get_response] [WARNING]- Not Found: /static/blog/js/up/js.js
2017-07-06 17:11:27,621 [Thread-9:2808] [django.request:124] [exception:handle_uncaught_exception] [ERROR]- Internal Server Error: /blog/tag/14/
Traceback (most recent call last):
  File "D:\files\anaconda3\lib\site-packages\django\core\handlers\exception.py", line 39, in inner
    response = get_response(request)
  File "D:\files\anaconda3\lib\site-packages\django\core\handlers\base.py", line 249, in _legacy_get_response
    response = self._get_response(request)
  File "D:\files\anaconda3\lib\site-packages\django\core\handlers\base.py", line 187, in _get_response
    response = self.process_exception_by_middleware(e, request)
  File "D:\files\anaconda3\lib\site-packages\django\core\handlers\base.py", line 185, in _get_response
    response = wrapped_callback(request, *callback_args, **callback_kwargs)
  File "D:\BLOG\blog\views.py", line 53, in page
    blogs = [Article.objects.all()[0] for i in range(8)]
  File "D:\BLOG\blog\views.py", line 53, in <listcomp>
    blogs = [Article.objects.all()[0] for i in range(8)]
  File "D:\files\anaconda3\lib\site-packages\django\db\models\query.py", line 295, in __getitem__
    return list(qs)[0]
IndexError: list index out of range
2017-07-06 17:12:13,052 [Thread-2:3980] [django.request:124] [exception:handle_uncaught_exception] [ERROR]- Internal Server Error: /blog/tag/14/
Traceback (most recent call last):
  File "D:\files\anaconda3\lib\site-packages\django\core\handlers\exception.py", line 39, in inner
    response = get_response(request)
  File "D:\files\anaconda3\lib\site-packages\django\core\handlers\base.py", line 249, in _legacy_get_response
    response = self._get_response(request)
  File "D:\files\anaconda3\lib\site-packages\django\core\handlers\base.py", line 187, in _get_response
    response = self.process_exception_by_middleware(e, request)
  File "D:\files\anaconda3\lib\site-packages\django\core\handlers\base.py", line 185, in _get_response
    response = wrapped_callback(request, *callback_args, **callback_kwargs)
  File "D:\BLOG\blog\views.py", line 53, in page
    blogs = [Article.objects.all()[0] for i in range(8)]
  File "D:\BLOG\blog\views.py", line 53, in <listcomp>
    blogs = [Article.objects.all()[0] for i in range(8)]
  File "D:\files\anaconda3\lib\site-packages\django\db\models\query.py", line 295, in __getitem__
    return list(qs)[0]
IndexError: list index out of range
2017-07-06 17:17:36,753 [Thread-59:7292] [django.request:152] [base:get_response] [WARNING]- Not Found: /favicon.ico
2017-07-06 17:23:28,489 [Thread-197:7960] [django.request:152] [base:get_response] [WARNING]- Not Found: /blog/rss/
